<robot name="vss">
    <link name="body">
        <inertial>
            <origin xyz="0.0 0.0 -0.024" rpy="0.0 0.0 0.0"/>
            <mass value="0.296"/>
        </inertial>
        <visual>
            <geometry>
                <box size="0.08 0.08 0.056"/>
            </geometry>
            <material name="Black">
                <color rgba="0 0.0 0.0 1.0"/>
            </material>
        </visual>
        <collision>
            <geometry>
                <box size="0.08 0.08 0.056"/>
            </geometry>
        </collision>
    </link>

    <link name="leftWheel">
        <inertial>
            <mass value="0.021"/>
        </inertial>
        <visual>
            <geometry>
                <cylinder radius="0.026" length="0.0025"/>
            </geometry>
        </visual>
        <collision>
            <geometry>
                <sphere radius="0.026"/>
            </geometry>
            <surface>
                <friction>
                    <ode>
                        <mu>0.8413767350560942</mu>
                        <mu2>1.0</mu2>
                    </ode>
                </friction>
            </surface>
        </collision>
    </link>

    <link name="rightWheel">
        <inertial>
            <mass value="0.021"/>
        </inertial>
        <visual>
            <geometry>
                <cylinder radius="0.026" length="0.0025"/>
            </geometry>
        </visual>
        <collision>
            <geometry>
                <sphere radius="0.026"/>
            </geometry>
            <surface>
                <friction>
                    <ode>
                        <mu>0.8413767350560942</mu>
                        <mu2>1.0</mu2>
                    </ode>
                </friction>
            </surface>
        </collision>
    </link>

    <joint name="body_leftWheel" type="continuous">
        <origin xyz="0.0 0.03375 -0.005" rpy="-1.570796 0.0 0.0" />
        <axis xyz="0.0 0.0 1.0"/>
        <parent link="body" />
        <child link="leftWheel" />
        <limit effort="0.0211" velocity="133.0"/>
    </joint>

    <joint name="body_rightWheel" type="continuous">
        <origin xyz="0.0 -0.03375 -0.005" rpy="-1.570796 0.0 0.0"/>
        <axis xyz="0.0 0.0 1.0"/>
        <parent link="body" />
        <child link="rightWheel" />
        <limit effort="0.0211" velocity="133.0"/>
    </joint>

    <link name="tagId">
        <visual>
            <geometry>
                <box size="0.03 0.05 0.001"/>
            </geometry>
        </visual>
    </link>
    <link name="tagTeam">
        <visual>
            <geometry>
                <box size="0.03 0.05 0.001"/>
            </geometry>
        </visual>
    </link>

    <joint name="body_tagId" type="fixed">
        <origin xyz="0.0175 0.0 0.028"/>
        <parent link="body" />
        <child link="tagId" />
    </joint>
    <joint name="body_tagTeam" type="fixed">
        <origin xyz="-0.0175 0.0 0.028"/>
        <parent link="body" />
        <child link="tagTeam" />
    </joint>

</robot>